=============`date`===================
/home/tom/.pyenv/versions/3.11.10/lib/python3.11/site-packages/pytest_asyncio/plugin.py:208: PytestDeprecationWarning: The configuration option "asyncio_default_fixture_loop_scope" is unset.
The event loop scope for asynchronous fixtures will default to the fixture caching scope. Future versions of pytest-asyncio will default the loop scope for asynchronous fixtures to function scope. Set the default fixture loop scope explicitly in order to avoid unexpected behavior in the future. Valid fixture loop scopes are: "function", "class", "module", "package", "session"

  warnings.warn(PytestDeprecationWarning(_DEFAULT_FIXTURE_LOOP_SCOPE_UNSET))
============================= test session starts ==============================
platform linux -- Python 3.11.10, pytest-8.3.4, pluggy-1.5.0
testmon: changed files: 0, unchanged files: 0, environment: default
Test order randomisation NOT enabled. Enable with --random-order or --random-order-bucket=<bucket_type>
rootdir: /home/tom/worktrees/simple_test_project/add_a_simple_script_that_shows_the_current_eth_pri_20250318_102211
plugins: mock-3.14.0, asyncio-0.24.0, testmon-2.1.3, anyio-4.9.0, timeout-2.3.1, repeat-0.9.3, xdist-3.6.1, cov-6.0.0, flake8-1.3.0, hypothesis-6.121.2, random-order-1.1.1, pylint-0.21.0
asyncio: mode=Mode.STRICT, default_loop_scope=None
timeout: 10.0s
timeout method: signal
timeout func_only: False
collected 1 item

tests/test_show_time.py .                                                [100%]

============================== 1 passed in 0.27s ===============================





=====================================================================
No files to lint: exiting.
Focus on code that causes this test to fail: 
Focus on fixing the linting issues
def test_show_time():
    assert True
