/home/tom/.pyenv/versions/3.11.10/lib/python3.11/site-packages/pytest_asyncio/plugin.py:208: PytestDeprecationWarning: The configuration option "asyncio_default_fixture_loop_scope" is unset.
The event loop scope for asynchronous fixtures will default to the fixture caching scope. Future versions of pytest-asyncio will default the loop scope for asynchronous fixtures to function scope. Set the default fixture loop scope explicitly in order to avoid unexpected behavior in the future. Valid fixture loop scopes are: "function", "class", "module", "package", "session"

  warnings.warn(PytestDeprecationWarning(_DEFAULT_FIXTURE_LOOP_SCOPE_UNSET))
Error fetching data: 429 Client Error: Too Many Requests for url: 
https://api.coingecko.com/api/v3/simple/price?ids=ethereum&vs_currencies=usd
================================================= test session starts ==================================================
platform linux -- Python 3.11.10, pytest-8.3.4, pluggy-1.5.0
Test order randomisation NOT enabled. Enable with --random-order or --random-order-bucket=<bucket_type>
rootdir: /home/tom/worktrees/simple_test_project/please_create_a_script_that_has_a_cli_with_help_me_20250318_102833
plugins: mock-3.14.0, asyncio-0.24.0, testmon-2.1.3, anyio-4.9.0, timeout-2.3.1, repeat-0.9.3, xdist-3.6.1, cov-6.0.0, flake8-1.3.0, hypothesis-6.121.2, random-order-1.1.1, pylint-0.21.0
asyncio: mode=Mode.STRICT, default_loop_scope=None
timeout: 1.0s
timeout method: signal
timeout func_only: False
collected 0 items
INTERNALERROR> Traceback (most recent call last):
INTERNALERROR>   File "/home/tom/worktrees/simple_test_project/please_create_a_script_that_has_a_cli_with_help_me_20250318_102833/show_time.py", line 23, in <module>
INTERNALERROR>     response.raise_for_status()  # Raise HTTPError for bad responses (4xx or 5xx)
INTERNALERROR>     ^^^^^^^^^^^^^^^^^^^^^^^^^^^
INTERNALERROR>   File "/home/tom/.pyenv/versions/3.11.10/lib/python3.11/site-packages/requests/models.py", line 1024, in raise_for_status
INTERNALERROR>     raise HTTPError(http_error_msg, response=self)
INTERNALERROR> requests.exceptions.HTTPError: 429 Client Error: Too Many Requests for url: https://api.coingecko.com/api/v3/simple/price?ids=ethereum&vs_currencies=usd
INTERNALERROR> 
INTERNALERROR> During handling of the above exception, another exception occurred:
INTERNALERROR> 
INTERNALERROR> Traceback (most recent call last):
INTERNALERROR>   File "/home/tom/.pyenv/versions/3.11.10/lib/python3.11/site-packages/_pytest/main.py", line 283, in wrap_session
INTERNALERROR>     session.exitstatus = doit(config, session) or 0
INTERNALERROR>                          ^^^^^^^^^^^^^^^^^^^^^
INTERNALERROR>   File "/home/tom/.pyenv/versions/3.11.10/lib/python3.11/site-packages/_pytest/main.py", line 336, in _main
INTERNALERROR>     config.hook.pytest_collection(session=session)
INTERNALERROR>   File "/home/tom/.pyenv/versions/3.11.10/lib/python3.11/site-packages/pluggy/_hooks.py", line 513, in __call__
INTERNALERROR>     return self._hookexec(self.name, self._hookimpls.copy(), kwargs, firstresult)
INTERNALERROR>            ^^^^^^^^^^^^^^^^^^^^^^^^^^^^^^^^^^^^^^^^^^^^^^^^^^^^^^^^^^^^^^^^^^^^^^
INTERNALERROR>   File "/home/tom/.pyenv/versions/3.11.10/lib/python3.11/site-packages/pluggy/_manager.py", line 120, in _hookexec
INTERNALERROR>     return self._inner_hookexec(hook_name, methods, kwargs, firstresult)
INTERNALERROR>            ^^^^^^^^^^^^^^^^^^^^^^^^^^^^^^^^^^^^^^^^^^^^^^^^^^^^^^^^^^^^^
INTERNALERROR>   File "/home/tom/.pyenv/versions/3.11.10/lib/python3.11/site-packages/pluggy/_callers.py", line 139, in _multicall
INTERNALERROR>     raise exception.with_traceback(exception.__traceback__)
INTERNALERROR>   File "/home/tom/.pyenv/versions/3.11.10/lib/python3.11/site-packages/pluggy/_callers.py", line 122, in _multicall
INTERNALERROR>     teardown.throw(exception)  # type: ignore[union-attr]
INTERNALERROR>     ^^^^^^^^^^^^^^^^^^^^^^^^^
INTERNALERROR>   File "/home/tom/.pyenv/versions/3.11.10/lib/python3.11/site-packages/_pytest/logging.py", line 790, in pytest_collection
INTERNALERROR>     return (yield)
INTERNALERROR>             ^^^^^
INTERNALERROR>   File "/home/tom/.pyenv/versions/3.11.10/lib/python3.11/site-packages/pluggy/_callers.py", line 122, in _multicall
INTERNALERROR>     teardown.throw(exception)  # type: ignore[union-attr]
INTERNALERROR>     ^^^^^^^^^^^^^^^^^^^^^^^^^
INTERNALERROR>   File "/home/tom/.pyenv/versions/3.11.10/lib/python3.11/site-packages/_pytest/warnings.py", line 121, in pytest_collection
INTERNALERROR>     return (yield)
INTERNALERROR>             ^^^^^
INTERNALERROR>   File "/home/tom/.pyenv/versions/3.11.10/lib/python3.11/site-packages/pluggy/_callers.py", line 122, in _multicall
INTERNALERROR>     teardown.throw(exception)  # type: ignore[union-attr]
INTERNALERROR>     ^^^^^^^^^^^^^^^^^^^^^^^^^
INTERNALERROR>   File "/home/tom/.pyenv/versions/3.11.10/lib/python3.11/site-packages/_pytest/config/__init__.py", line 1417, in pytest_collection
INTERNALERROR>     return (yield)
INTERNALERROR>             ^^^^^
INTERNALERROR>   File "/home/tom/.pyenv/versions/3.11.10/lib/python3.11/site-packages/pluggy/_callers.py", line 103, in _multicall
INTERNALERROR>     res = hook_impl.function(*args)
INTERNALERROR>           ^^^^^^^^^^^^^^^^^^^^^^^^^
INTERNALERROR>   File "/home/tom/.pyenv/versions/3.11.10/lib/python3.11/site-packages/_pytest/main.py", line 347, in pytest_collection
INTERNALERROR>     session.perform_collect()
INTERNALERROR>   File "/home/tom/.pyenv/versions/3.11.10/lib/python3.11/site-packages/_pytest/main.py", line 809, in perform_collect
INTERNALERROR>     self.items.extend(self.genitems(node))
INTERNALERROR>   File "/home/tom/.pyenv/versions/3.11.10/lib/python3.11/site-packages/_pytest/main.py", line 970, in genitems
INTERNALERROR>     rep, duplicate = self._collect_one_node(node, handle_dupes)
INTERNALERROR>                      ^^^^^^^^^^^^^^^^^^^^^^^^^^^^^^^^^^^^^^^^^^
INTERNALERROR>   File "/home/tom/.pyenv/versions/3.11.10/lib/python3.11/site-packages/_pytest/main.py", line 835, in _collect_one_node
INTERNALERROR>     rep = collect_one_node(node)
INTERNALERROR>           ^^^^^^^^^^^^^^^^^^^^^^
INTERNALERROR>   File "/home/tom/.pyenv/versions/3.11.10/lib/python3.11/site-packages/_pytest/runner.py", line 567, in collect_one_node
INTERNALERROR>     rep: CollectReport = ihook.pytest_make_collect_report(collector=collector)
INTERNALERROR>                          ^^^^^^^^^^^^^^^^^^^^^^^^^^^^^^^^^^^^^^^^^^^^^^^^^^^^^
INTERNALERROR>   File "/home/tom/.pyenv/versions/3.11.10/lib/python3.11/site-packages/pluggy/_hooks.py", line 513, in __call__
INTERNALERROR>     return self._hookexec(self.name, self._hookimpls.copy(), kwargs, firstresult)
INTERNALERROR>            ^^^^^^^^^^^^^^^^^^^^^^^^^^^^^^^^^^^^^^^^^^^^^^^^^^^^^^^^^^^^^^^^^^^^^^
INTERNALERROR>   File "/home/tom/.pyenv/versions/3.11.10/lib/python3.11/site-packages/pluggy/_manager.py", line 120, in _hookexec
INTERNALERROR>     return self._inner_hookexec(hook_name, methods, kwargs, firstresult)
INTERNALERROR>            ^^^^^^^^^^^^^^^^^^^^^^^^^^^^^^^^^^^^^^^^^^^^^^^^^^^^^^^^^^^^^
INTERNALERROR>   File "/home/tom/.pyenv/versions/3.11.10/lib/python3.11/site-packages/pluggy/_callers.py", line 139, in _multicall
INTERNALERROR>     raise exception.with_traceback(exception.__traceback__)
INTERNALERROR>   File "/home/tom/.pyenv/versions/3.11.10/lib/python3.11/site-packages/pluggy/_callers.py", line 122, in _multicall
INTERNALERROR>     teardown.throw(exception)  # type: ignore[union-attr]
INTERNALERROR>     ^^^^^^^^^^^^^^^^^^^^^^^^^
INTERNALERROR>   File "/home/tom/.pyenv/versions/3.11.10/lib/python3.11/site-packages/_pytest/capture.py", line 860, in pytest_make_collect_report
INTERNALERROR>     rep = yield
INTERNALERROR>           ^^^^^
INTERNALERROR>   File "/home/tom/.pyenv/versions/3.11.10/lib/python3.11/site-packages/pluggy/_callers.py", line 103, in _multicall
INTERNALERROR>     res = hook_impl.function(*args)
INTERNALERROR>           ^^^^^^^^^^^^^^^^^^^^^^^^^
INTERNALERROR>   File "/home/tom/.pyenv/versions/3.11.10/lib/python3.11/site-packages/_pytest/runner.py", line 391, in pytest_make_collect_report
INTERNALERROR>     call = CallInfo.from_call(
INTERNALERROR>            ^^^^^^^^^^^^^^^^^^^
INTERNALERROR>   File "/home/tom/.pyenv/versions/3.11.10/lib/python3.11/site-packages/_pytest/runner.py", line 341, in from_call
INTERNALERROR>     result: TResult | None = func()
INTERNALERROR>                              ^^^^^^
INTERNALERROR>   File "/home/tom/.pyenv/versions/3.11.10/lib/python3.11/site-packages/_pytest/runner.py", line 389, in collect
INTERNALERROR>     return list(collector.collect())
INTERNALERROR>                 ^^^^^^^^^^^^^^^^^^^
INTERNALERROR>   File "/home/tom/.pyenv/versions/3.11.10/lib/python3.11/site-packages/pytest_asyncio/plugin.py", line 667, in _patched_collect
INTERNALERROR>     module = collector.obj
INTERNALERROR>              ^^^^^^^^^^^^^
INTERNALERROR>   File "/home/tom/.pyenv/versions/3.11.10/lib/python3.11/site-packages/_pytest/python.py", line 284, in objmainloop: caught unexpected SystemExit!

INTERNALERROR>     self._obj = obj = self._getobj()
INTERNALERROR>                       ^^^^^^^^^^^^^^
INTERNALERROR>   File "/home/tom/.pyenv/versions/3.11.10/lib/python3.11/site-packages/_pytest/python.py", line 546, in _getobj
INTERNALERROR>     return importtestmodule(self.path, self.config)
INTERNALERROR>            ^^^^^^^^^^^^^^^^^^^^^^^^^^^^^^^^^^^^^^^^
INTERNALERROR>   File "/home/tom/.pyenv/versions/3.11.10/lib/python3.11/site-packages/_pytest/python.py", line 493, in importtestmodule
INTERNALERROR>     mod = import_path(
INTERNALERROR>           ^^^^^^^^^^^^
INTERNALERROR>   File "/home/tom/.pyenv/versions/3.11.10/lib/python3.11/site-packages/_pytest/pathlib.py", line 587, in import_path
INTERNALERROR>     importlib.import_module(module_name)
INTERNALERROR>   File "/home/tom/.pyenv/versions/3.11.10/lib/python3.11/importlib/__init__.py", line 126, in import_module
INTERNALERROR>     return _bootstrap._gcd_import(name[level:], package, level)
INTERNALERROR>            ^^^^^^^^^^^^^^^^^^^^^^^^^^^^^^^^^^^^^^^^^^^^^^^^^^^^
INTERNALERROR>   File "<frozen importlib._bootstrap>", line 1204, in _gcd_import
INTERNALERROR>   File "<frozen importlib._bootstrap>", line 1176, in _find_and_load
INTERNALERROR>   File "<frozen importlib._bootstrap>", line 1147, in _find_and_load_unlocked
INTERNALERROR>   File "<frozen importlib._bootstrap>", line 690, in _load_unlocked
INTERNALERROR>   File "/home/tom/.pyenv/versions/3.11.10/lib/python3.11/site-packages/_pytest/assertion/rewrite.py", line 184, in exec_module
INTERNALERROR>     exec(co, module.__dict__)
INTERNALERROR>   File "/home/tom/worktrees/simple_test_project/please_create_a_script_that_has_a_cli_with_help_me_20250318_102833/show_time.py", line 26, in <module>
INTERNALERROR>     sys.exit(1)
INTERNALERROR> SystemExit: 1

================================================ no tests ran in 0.30s =================================================
************* Module **.*
**/*.py:1:0: C0103: Module name "*" doesn't conform to snake_case naming style (invalid-name)

------------------------------------------------------------------
Your code has been rated at 9.67/10 (previous run: 9.67/10, +0.00)

